<robot name="prototype3">
    <material name="Blue">
        <texture />
        <color rgba="0 0 1 1" />
    </material>
    <material name="DarkGrey">
        <texture />
        <color rgba="0.3 0.3 0.3 1" />
    </material>
    <material name="Grey">
        <texture />
        <color rgba="0.5 0.5 0.5 1" />
    </material>
    <material name="LightGrey">
        <texture />
        <color rgba="0.7 0.7 0.7 1" />
    </material>
    <link name="base">
        <visual>
            <origin xyz="0 0 0.1" rpy="0 -0 0" />
            <geometry>
                <cylinder radius="0.1" length="0.2" />
            </geometry>
            <material name="DarkGrey">
                <texture />
                <color rgba="0.3 0.3 0.3 1" />
            </material>
        </visual>
    </link>
    <link name="flange">
        <inertial>
            <mass value="2" />
            <origin xyz="0 0 0" rpy="0 -0 0" />
            <inertia ixx="0" ixy="0" ixz="0" iyy="0" iyz="0" izz="0" />
        </inertial>
        <visual>
            <origin xyz="0 0 -0.0082" rpy="0 -0 0" />
            <geometry>
                <cylinder radius="0.05" length="0.0164" />
            </geometry>
            <material name="Grey">
                <texture />
                <color rgba="0.5 0.5 0.5 1" />
            </material>
        </visual>
    </link>
    <link name="link1">
        <inertial>
            <mass value="-7.60806e-23" />
            <origin xyz="0 0 0" rpy="0 -0 0" />
            <inertia ixx="-5.04216e-22" ixy="-4.98279e-21" ixz="-3.19413e-22" iyy="8.96624e-21" iyz="-1.0395e-23" izz="-0.0318606" />
        </inertial>
        <visual>
            <origin xyz="0 0 0.27645" rpy="0 -0 0" />
            <geometry>
                <cylinder radius="0.1" length="0.1529" />
            </geometry>
            <material name="Grey">
                <texture />
                <color rgba="0.5 0.5 0.5 1" />
            </material>
        </visual>
    </link>
    <link name="link2">
        <inertial>
            <mass value="-2.07059e-21" />
            <origin xyz="0 0 0" rpy="0 -0 0" />
            <inertia ixx="-0.606638" ixy="0.848326" ixz="0.596863" iyy="0.574778" iyz="1.51513" izz="-4.32432" />
        </inertial>
        <visual>
            <origin xyz="0 0.239 0" rpy="1.5708 -0 0" />
            <geometry>
                <cylinder radius="0.05" length="0.478" />
            </geometry>
            <material name="LightGrey">
                <texture />
                <color rgba="0.7 0.7 0.7 1" />
            </material>
        </visual>
    </link>
    <link name="link3">
        <inertial>
            <mass value="-1.56831" />
            <origin xyz="1.05094 -0.0607655 9.13216e-16" rpy="0 -0 0" />
            <inertia ixx="1.14921" ixy="0.368304" ixz="-0.927037" iyy="-1.18107" iyz="-1.73154" izz="0.193509" />
        </inertial>
        <visual>
            <origin xyz="0 -0.0178 0" rpy="0 -0 0" />
            <geometry>
                <cylinder radius="0.1" length="0.0356" />
            </geometry>
            <material name="Blue">
                <texture />
                <color rgba="0 0 1 1" />
            </material>
        </visual>
    </link>
    <link name="link4">
        <inertial>
            <mass value="-1.54257" />
            <origin xyz="-0.0323636 0.816197 1.06848" rpy="0 -0 0" />
            <inertia ixx="-0.573029" ixy="0.783351" ixz="0.0868912" iyy="-0.414539" iyz="0.266375" izz="0.43071" />
        </inertial>
        <visual>
            <origin xyz="0 0 0.18525" rpy="0 -0 0" />
            <geometry>
                <cylinder radius="0.05" length="0.3905" />
            </geometry>
            <material name="LightGrey">
                <texture />
                <color rgba="0.7 0.7 0.7 1" />
            </material>
        </visual>
    </link>
    <link name="link5">
        <inertial>
            <mass value="-7.08023" />
            <origin xyz="-0.00598452 -0.0103627 0.177824" rpy="0 -0 0" />
            <inertia ixx="-0.0410445" ixy="0.48689" ixz="0.187407" iyy="-0.101271" iyz="-0.255866" izz="-0.476717" />
        </inertial>
        <visual>
            <origin xyz="0 0 0.07725" rpy="0 -0 0" />
            <geometry>
                <cylinder radius="0.05" length="0.1445" />
            </geometry>
            <material name="Blue">
                <texture />
                <color rgba="0 0 1 1" />
            </material>
        </visual>
    </link>
    <link name="link6">
        <inertial>
            <mass value="19.2493" />
            <origin xyz="0.00109173 -0.000652954 0.00381184" rpy="0 -0 0" />
            <inertia ixx="-0.158019" ixy="-0.261566" ixz="0.0925428" iyy="-0.359744" iyz="0.312338" izz="0.283617" />
        </inertial>
        <visual>
            <origin xyz="0 0 0.125" rpy="0 -0 0" />
            <geometry>
                <cylinder radius="0.05" length="0.25" />
            </geometry>
            <material name="LightGrey">
                <texture />
                <color rgba="0.7 0.7 0.7 1" />
            </material>
        </visual>
    </link>
    <joint name="flange_joint" type="fixed">
        <origin xyz="0 0 0" rpy="0 -0 0" />
        <axis xyz="0 0 0" />
        <parent link="link6" />
        <child link="flange" />
    </joint>
    <joint name="joint_1" type="revolute">
        <origin xyz="0 0 0" rpy="0 -0 0" />
        <axis xyz="0 0 1" />
        <parent link="base" />
        <child link="link1" />
        <limit effort="90" velocity="1" lower="-2.9" upper="2.9" />
    </joint>
    <joint name="joint_2" type="revolute">
        <origin xyz="0 0 0.3529" rpy="1.5708 -0 0" />
        <axis xyz="0 0 1" />
        <parent link="link1" />
        <child link="link2" />
        <limit effort="90" velocity="1" lower="-2.1" upper="2.1" />
    </joint>
    <joint name="joint_3" type="revolute">
        <origin xyz="0 0.478 0" rpy="0 -0 1.5708" />
        <axis xyz="0 0 1" />
        <parent link="link2" />
        <child link="link3" />
        <limit effort="51" velocity="0.5" lower="-2.9" upper="2.9" />
    </joint>
    <joint name="joint_4" type="revolute">
        <origin xyz="0 0 -0.0356" rpy="1.5708 -0 1.5708" />
        <axis xyz="0 0 1" />
        <parent link="link3" />
        <child link="link4" />
        <limit effort="51" velocity="0.5" lower="-2.9" upper="2.9" />
    </joint>
    <joint name="joint_5" type="revolute">
        <origin xyz="0 0 0.3905" rpy="1.5708 -4.23516e-22 -3.14159" />
        <axis xyz="0 0 1" />
        <parent link="link4" />
        <child link="link5" />
        <limit effort="51" velocity="0.5" lower="-2.5" upper="2.5" />
    </joint>
    <joint name="joint_6" type="revolute">
        <origin xyz="0 0 0.1445" rpy="-1.5708 0 0" />
        <axis xyz="0 0 1" />
        <parent link="link5" />
        <child link="link6" />
        <limit effort="51" velocity="0.5" lower="-2.9" upper="2.9" />
    </joint>
</robot>
