 <robot name="prototype3">
   <material name="Blue">
      <color rgba="0 0.0 1.0 1.0"/>
    </material>
    <material name="Grey">
      <color rgba="0.5 0.5 0.5 1.0"/>
    </material>
    <material name="LightGrey">
      <color rgba="0.7 0.7 0.7 1.0"/>
    </material>
    <material name="DarkGrey">
      <color rgba="0.3 0.3 0.3 1.0"/>
    </material>
  <link name="base" >
    <visual>
      <origin xyz="0 0 0.1" rpy="0 0 0" />
      <geometry>
        <cylinder length="0.2" radius="0.1"/>
      </geometry>
      <material name="DarkGrey">
      </material>
    </visual>
  </link>
  
  <link name="link1" >
    <visual>
      <origin xyz="0 0 0.27645" rpy="0 0 0" />
      <geometry>
        <cylinder length="0.15290" radius="0.1"/>
      </geometry>
      <material name="Grey">
        <color rgba="1.0 0.0 0.0 1.0"/>
      </material>
    </visual>
  </link>   

  <link name="link2" >
    <visual>
      <origin xyz="0 0.1625 0" rpy="1.5708 0 0" />
      <geometry>
        <cylinder length="0.32500" radius="0.05"/>  <!-- 0.478 -->
      </geometry>
      <material name="LightGrey">
      </material>
    </visual>
  </link>   

  <link name="link3" >
    <visual>
      <origin xyz="0 -0.0178 0" rpy="0 0 0" />
      <geometry>
        <cylinder length="0.03560" radius="0.1"/>
      </geometry>
      <material name="Blue">
      </material>
    </visual>
    <inertial>
      <origin
        xyz="0.0 0.0 0.0"
        rpy="0 0 0" />
      <mass
         value="7.0" />  <!--8.0-->
      <inertia
        ixx="0.0"
        ixy="0.0"
        ixz="0.0"
        iyy="0.0"
        iyz="0.0"
        izz="0.0" />
    </inertial>
  </link>   
  
  <link name="link4" >
    <visual>
      <origin xyz="0 0 0.18525" rpy="0 0 0" />
      <geometry>
        <cylinder length="0.39050" radius="0.05"/>
      </geometry>
      <material name="LightGrey">
      </material>
      </visual>
          <inertial>
        <origin
          xyz="0.0 0.0 0.0"
          rpy="0 0 0" />
        <mass
          value="2.0" />   <!--2.0-->
        <inertia
          ixx="0.0"
          ixy="0.0"
          ixz="0.0"
          iyy="0.0"
          iyz="0.0"
          izz="0.0" />
      </inertial>
  </link>    
  
  <link name="link5" >
    <visual>
      <origin xyz="0 0 0.07725" rpy="0 0 0" />
      <geometry>
        <cylinder length="0.14450" radius="0.05"/>
      </geometry>
      <material name="Blue">
      </material>
    </visual>
  </link>   
  
  <link name="link6" >
    <visual>
      <origin xyz="0 0 0.125" rpy="0 0 0" />
      <geometry>
        <cylinder length="0.25" radius="0.05"/>
      </geometry>
      <material name="LightGrey">
      </material>
    </visual>
  </link>    
  
  <link name="flange" >
    <visual>
      <origin xyz="0 0 -0.0082" rpy="0 0 0" />
      <geometry>
        <cylinder length="0.01640" radius="0.05"/>
      </geometry>
      <material name="Grey">
      </material>
    </visual>
    <inertial>
      <origin
        xyz="0.0 0.0 0.0"
        rpy="0 0 0" />
      <mass
        value="2.0" />   <!--2.0-->
      <inertia
        ixx="0.0"
        ixy="0.0"
        ixz="0.0"
        iyy="0.0"
        iyz="0.0"
        izz="0.0" />
    </inertial>
  </link>   
  
  <joint name="flange_joint" type="fixed">
    <origin xyz="0 0 0" rpy="0 -0 0" />
    <axis xyz="0 0 1" />
    <parent link="link6" />
    <child link="flange" />
  </joint>
  
  <joint name="joint_1" type="revolute">
    <origin xyz="0 0 0" rpy="0 -0 0" />
    <axis xyz="0 0 1" />
    <parent link="base" />
    <child link="link1" />
    <limit effort="90" velocity="1.0" lower="-2.9" upper="2.9" />
  </joint>
  <joint name="joint_2" type="revolute">
    <origin xyz="0 0 0.3529" rpy="1.5708 -0 0" />
    <axis xyz="0 0 1" />
    <parent link="link1" />
    <child link="link2" />
    <limit effort="90" velocity="1.0" lower="-2.1" upper="2.1" />
  </joint>
  <joint name="joint_3" type="revolute">
    <origin xyz="0 0.325 0" rpy="0 -0 1.5708" />
    <axis xyz="0 0 1" />
    <parent link="link2" />
    <child link="link3" />
    <limit effort="51" velocity="0.5" lower="-2.9" upper="2.9" />
  </joint>
  <joint name="joint_4" type="revolute">
    <origin xyz="0 0 -0.0356" rpy="1.5708 -0 1.5708" />
    <axis xyz="0 0 1" />
    <parent link="link3" />
    <child link="link4" />
    <limit effort="51" velocity="0.5" lower="-2.9" upper="2.9" />
  </joint>
  <joint name="joint_5" type="revolute">
    <origin xyz="0 0 0.3905" rpy="1.5708 -4.23516e-22 -3.14159" />
    <axis xyz="0 0 1" />
    <parent link="link4" />
    <child link="link5" />
    <limit effort="51" velocity="0.5" lower="-2.5" upper="2.5" />
  </joint>
  <joint name="joint_6" type="revolute">
    <origin xyz="0 0 0.1445" rpy="-1.5708 0 0" />
    <axis xyz="0 0 1" />
    <parent link="link5" />
    <child link="link6" />
    <limit effort="51" velocity="0.5" lower="-2.9" upper="2.9" />
  </joint>
  
</robot>
