<robot name="prototype4">
    <material name="Blue">
        <texture />
        <color rgba="0 0 1 1" />
    </material>
    <material name="DarkGrey">
        <texture />
        <color rgba="0.3 0.3 0.3 1" />
    </material>
    <material name="Grey">
        <texture />
        <color rgba="0.5 0.5 0.5 1" />
    </material>
    <material name="LightGrey">
        <texture />
        <color rgba="0.7 0.7 0.7 1" />
    </material>
    <link name="base">
        <visual>
            <origin xyz="0 0 0" rpy="0 0 3.14159" />
            <geometry>
                <mesh filename="package://fourbythree_description/meshes/prototype4_base.stl" scale="1 1 1" />
            </geometry>
            <material name="LightGrey">
                <texture />
                <color rgba="0.7 0.7 0.7 1" />
            </material>
        </visual>
    </link>
    <link name="flange">
        <inertial>
            <mass value="-0.34298" />
            <origin xyz="-0.0573765 -0.0770548 -0.408675" rpy="0 -0 0" />
            <inertia ixx="0.0312762" ixy="-0.0594233" ixz="-0.0399678" iyy="0.116942" iyz="-0.00521424" izz="0.0024152" />
        </inertial>
    </link>
    <link name="flange_rotZ">
        <inertial>
            <mass value="-0.34298" />
            <origin xyz="-0.0573765 -0.0770548 -0.408675" rpy="0 -0 0" />
            <inertia ixx="0.0312762" ixy="-0.0594233" ixz="-0.0399678" iyy="0.116942" iyz="-0.00521424" izz="0.0024152" />
        </inertial>
        <visual>
            <origin xyz="0 0 0" rpy="0 -0 0" />
            <geometry>
                <mesh filename="package://fourbythree_description/meshes/prototype4_flange.stl" scale="1 1 1" />
            </geometry>
            <material name="LightGrey">
                <texture />
                <color rgba="0.7 0.7 0.7 1" />
            </material>
        </visual>
    </link>
    <link name="link1">
        <inertial>
            <mass value="9.88249e-28" />
            <origin xyz="0 0 0" rpy="0 -0 0" />
            <inertia ixx="-2.47387e-26" ixy="-1.49995e-21" ixz="-6.06105e-28" iyy="0.0908589" iyz="8.89755e-13" izz="-9.78536e-26" />
        </inertial>
    </link>
    <link name="link1_rotZ">
        <inertial>
            <mass value="3.61643e-27" />
            <origin xyz="0 0 0" rpy="0 -0 0" />
            <inertia ixx="-5.89481e-27" ixy="1.36457e-27" ixz="-1.8585e-27" iyy="-2.47684e-28" iyz="3.06612e-27" izz="0.0908589" />
        </inertial>
        <visual>
            <origin xyz="0 -0.03 -0.02" rpy="0 0 -1.5708" />
            <geometry>
                <mesh filename="package://fourbythree_description/meshes/prototype4_link1.stl" scale="1 1 1" />
            </geometry>
            <material name="LightGrey">
                <texture />
                <color rgba="0.7 0.7 0.7 1" />
            </material>
        </visual>
    </link>
    <link name="link2">
        <inertial>
            <mass value="1.82733" />
            <origin xyz="1.58588 -0.0232431 1.23947e-16" rpy="0 -0 0" />
            <inertia ixx="-0.365793" ixy="0.504633" ixz="-0.197136" iyy="0.456652" iyz="-0.589079" izz="-0.633498" />
        </inertial>
    </link>
    <link name="link2_rotZ">
        <inertial>
            <mass value="1.04466e-27" />
            <origin xyz="0 0 0" rpy="0 -0 0" />
            <inertia ixx="-0.365793" ixy="0.504633" ixz="-0.197136" iyy="0.456652" iyz="-0.589079" izz="-0.633498" />
        </inertial>
        <visual>
            <origin xyz="0 0 0.09" rpy="0 -1.5708 3.1416" />
            <geometry>
                <mesh filename="package://fourbythree_description/meshes/prototype4_link2.stl" scale="1 1 1" />
            </geometry>
            <material name="LightGrey">
                <texture />
                <color rgba="0.7 0.7 0.7 1" />
            </material>
        </visual>
    </link>
    <link name="link3">
        <inertial>
            <mass value="1.82811" />
            <origin xyz="-0.0287967 2.09009e-12 0.42695" rpy="0 -0 0" />
            <inertia ixx="-0.0799702" ixy="0.0618795" ixz="-0.421262" iyy="-0.272532" iyz="0.267937" izz="0.170829" />
        </inertial>
    </link>
    <link name="link3_rotZ">
        <inertial>
            <mass value="1.82811" />
            <origin xyz="-0.0287967 0.42695 2.48262e-16" rpy="0 -0 0" />
            <inertia ixx="-0.0799702" ixy="-0.421262" ixz="-0.0618795" iyy="0.170829" iyz="-0.267937" izz="-0.272532" />
        </inertial>
        <visual>
            <origin xyz="0 0 0" rpy="0 -1.5708 -1.5708" />
            <geometry>
                <mesh filename="package://fourbythree_description/meshes/prototype4_link3.stl" scale="1 1 1" />
            </geometry>
            <material name="LightGrey">
                <texture />
                <color rgba="0.7 0.7 0.7 1" />
            </material>
        </visual>
    </link>
    <link name="link4">
        <inertial>
            <mass value="0.587124" />
            <origin xyz="-0.00107953 1.32938 0.0762394" rpy="0 -0 0" />
            <inertia ixx="0.0533065" ixy="-0.0440664" ixz="0.209402" iyy="-0.0250479" iyz="-0.0903782" izz="-0.405809" />
        </inertial>
    </link>
    <link name="link4_rotZ">
        <inertial>
            <mass value="0.587124" />
            <origin xyz="-0.00107953 -0.0762394 1.32938" rpy="0 -0 0" />
            <inertia ixx="0.0533065" ixy="-0.209402" ixz="-0.0440664" iyy="-0.405809" iyz="0.0903782" izz="-0.0250479" />
        </inertial>
        <visual>
            <origin xyz="0 0 -0.39" rpy="0 -0 1.5708" />
            <geometry>
                <mesh filename="package://fourbythree_description/meshes/prototype4_link4.stl" scale="1 1 1" />
            </geometry>
            <material name="LightGrey">
                <texture />
                <color rgba="0.7 0.7 0.7 1" />
            </material>
        </visual>
    </link>
    <link name="link5">
        <inertial>
            <mass value="0.587124" />
            <origin xyz="0.0213619 -0.0762394 0.238735" rpy="0 -0 0" />
            <inertia ixx="0.0684802" ixy="-0.0210941" ixz="0.00549821" iyy="0.0797379" iyz="-0.143362" izz="-0.0402216" />
        </inertial>
    </link>
    <link name="link5_rotZ">
        <inertial>
            <mass value="0.587124" />
            <origin xyz="0.0213619 0.238735 0.0762394" rpy="0 -0 0" />
            <inertia ixx="0.0684802" ixy="0.00549821" ixz="0.0210941" iyy="-0.0402216" iyz="0.143362" izz="0.0797379" />
        </inertial>
        <visual>
            <origin xyz="0 0 -0.01" rpy="0 1.5708 1.5708" />
            <geometry>
                <mesh filename="package://fourbythree_description/meshes/prototype4_link5.stl" scale="1 1 1" />
            </geometry>
            <material name="LightGrey">
                <texture />
                <color rgba="0.7 0.7 0.7 1" />
            </material>
        </visual>
    </link>
    <joint name="joint_1" type="revolute">
        <origin xyz="0 0 0.425" rpy="0 -0 0" />
        <axis xyz="0 0 1" />
        <parent link="base" />
        <child link="link1_rotZ" />
        <limit effort="250" velocity="0.5" lower="-2.8" upper="2.8" />
    </joint>
    <joint name="joint_1_fixed" type="fixed">
        <origin xyz="0 0 0" rpy="1.5708 -0 0" />
        <axis xyz="0 0 0" />
        <parent link="link1_rotZ" />
        <child link="link1" />
    </joint>
    <joint name="joint_2" type="revolute">
        <origin xyz="0 0 0" rpy="0 -0 1.5708" />
        <axis xyz="0 0 1" />
        <parent link="link1" />
        <child link="link2_rotZ" />
        <limit effort="250" velocity="0.5" lower="-1.8" upper="1.8" />
    </joint>
    <joint name="joint_2_fixed" type="fixed">
        <origin xyz="0.6569 0 0" rpy="0 -0 0" />
        <axis xyz="0 0 0" />
        <parent link="link2_rotZ" />
        <child link="link2" />
    </joint>
    <joint name="joint_3" type="revolute">
        <origin xyz="0 0 0.006" rpy="0 0 -1.5708" />
        <axis xyz="0 0 1" />
        <parent link="link2" />
        <child link="link3_rotZ" />
        <limit effort="90" velocity="0.5" lower="-2.5" upper="2.5" />
    </joint>
    <joint name="joint_3_fixed" type="fixed">
        <origin xyz="0 0 0" rpy="-1.5708 0 0" />
        <axis xyz="0 0 0" />
        <parent link="link3_rotZ" />
        <child link="link3" />
    </joint>
    <joint name="joint_4" type="revolute">
        <origin xyz="0 0 0.56345" rpy="0 -0 0" />
        <axis xyz="0 0 1" />
        <parent link="link3" />
        <child link="link4_rotZ" />
        <limit effort="40" velocity="0.5" lower="-2.8" upper="2.8" />
    </joint>
    <joint name="joint_4_fixed" type="fixed">
        <origin xyz="0 0 0" rpy="1.5708 -0 0" />
        <axis xyz="0 0 0" />
        <parent link="link4_rotZ" />
        <child link="link4" />
    </joint>
    <joint name="joint_5" type="revolute">
        <origin xyz="0 0 0" rpy="0 -0 0" />
        <axis xyz="0 0 1" />
        <parent link="link4" />
        <child link="link5_rotZ" />
        <limit effort="40" velocity="0.5" lower="-1.57" upper="1.57" />
    </joint>
    <joint name="joint_5_fixed" type="fixed">
        <origin xyz="0 0 0" rpy="-1.5708 0 0" />
        <axis xyz="0 0 0" />
        <parent link="link5_rotZ" />
        <child link="link5" />
    </joint>
    <joint name="joint_6" type="revolute">
        <origin xyz="0 0 0.26055" rpy="0 -0 0" />
        <axis xyz="0 0 1" />
        <parent link="link5" />
        <child link="flange_rotZ" />
        <limit effort="40" velocity="0.5" lower="-2.8" upper="2.8" />
    </joint>
    <joint name="joint_6_fixed" type="fixed">
        <origin xyz="0 0 0" rpy="0 -0 0" />
        <axis xyz="0 0 0" />
        <parent link="flange_rotZ" />
        <child link="flange" />
    </joint>
</robot>
