<?xml version="1.0" ?>
<!-- =================================================================================== -->
<!-- |    This document was autogenerated by xacro from fourbythree_urdf_template.urdf.xacro | -->
<!-- |    EDITING THIS FILE BY HAND IS NOT RECOMMENDED                                 | -->
<!-- =================================================================================== -->
<robot name="prototype4" xmlns:xacro="http://ros.org/wiki/xacro">
  
  
  <material name="Blue">
    <color rgba="0 0.0 1.0 1.0"/>
  </material>
  <material name="Grey">
    <color rgba="0.5 0.5 0.5 1.0"/>
  </material>
  <material name="LightGrey">
    <color rgba="0.7 0.7 0.7 1.0"/>
  </material>
  <material name="DarkGrey">
    <color rgba="0.3 0.3 0.3 1.0"/>
  </material>
  
  
  <!-- RADIANT -->
  <!-- Nm -->
  <!-- PI/2 = 1.5708-->
  <!-- PI   = 3.1416-->
  
  
  <link name="base">
    <visual>
      <origin xyz="0 0 0" rpy="0 0 -3.1416" />
      <geometry>
       <mesh filename="package://fourbythree_description/meshes/prototype4_base.stl"/>
      </geometry>
      <material name="LightGrey">
      </material>
    </visual>
  </link>
  
  
  
  <joint name="joint_1" type="revolute">
    <parent link="base"/>
    <child link="link1_rotZ"/>
    <origin rpy="0.0 0 0.0" xyz="0 0 0.425"/>
    <axis xyz="0 0 1"/>
    <limit effort="250" lower="-2.8" upper="2.8" velocity="0.5"/>
  </joint>
  <joint name="joint_1_fixed" type="fixed">
    <parent link="link1_rotZ"/>
    <child link="link1"/>
    <origin rpy="1.57079632679 0.0 0" xyz="0.0 0 0"/>
  </joint>
  <link name="link1_rotZ">
    <visual>
      <origin xyz="0 -0.03 -0.02" rpy="0 0 -1.5708 " />
      <geometry>
        <mesh filename="package://fourbythree_description/meshes/prototype4_link1.stl"/>
      </geometry>
      <material name="LightGrey">
      </material>
    </visual>
  </link>
  <link name="link1"/>
  
  
  
  <joint name="joint_2" type="revolute">
    <parent link="link1"/>
    <child link="link2_rotZ"/>
    <origin rpy="0.0 0 1.57079632679" xyz="0 0 0.0"/>
    <axis xyz="0 0 1"/>
    <limit effort="250" lower="-1.8" upper="1.8" velocity="0.5"/>
  </joint>
  <joint name="joint_2_fixed" type="fixed">
    <parent link="link2_rotZ"/>
    <child link="link2"/>
    <origin rpy="0.0 0.0 0" xyz="0.6569 0 0"/>
  </joint>
  <link name="link2_rotZ">
    <visual>
      <origin xyz="0 0 0.09 " rpy=" 0 -1.572 3.1416" />
      <geometry>
        <mesh filename="package://fourbythree_description/meshes/prototype4_link2.stl"/>
      </geometry>
      <material name="LightGrey">
      </material>
    </visual>
  </link>
  <link name="link2"/>
  

  
  <joint name="joint_3" type="revolute">
    <parent link="link2"/>
    <child link="link3_rotZ"/>
    <origin rpy="0.0 0 -1.57079632679" xyz="0 0 0.006"/>
    <axis xyz="0 0 1"/>
    <limit effort="90" lower="-2.5" upper="2.5" velocity="0.5"/>
  </joint>
  <joint name="joint_3_fixed" type="fixed">
    <parent link="link3_rotZ"/>
    <child link="link3"/>
    <origin rpy="-1.57079632679 0.0 0" xyz="0.0 0 0"/>
  </joint>
  <link name="link3_rotZ">
    <visual>
      <origin xyz=" 0 0 0 " rpy=" 0 -1.5708 -1.5708" />
      <geometry>
        <mesh filename="package://fourbythree_description/meshes/prototype4_link3.stl"/>
      </geometry>
      <material name="LightGrey">
      </material>
    </visual>
  </link>
  <link name="link3"/>
  
  
  
  <joint name="joint_4" type="revolute">
    <parent link="link3"/>
    <child link="link4_rotZ"/>
    <origin rpy="0.0 0 0.0" xyz="0 0 0.56345"/>
    <axis xyz="0 0 1"/>
    <limit effort="40" lower="-2.8" upper="2.8" velocity="0.5"/>
  </joint>
  <joint name="joint_4_fixed" type="fixed">
    <parent link="link4_rotZ"/>
    <child link="link4"/>
    <origin rpy="1.57079632679 0.0 0" xyz="0.0 0 0"/>
  </joint>
  <link name="link4_rotZ">
    <visual>
      <origin xyz="0 0 -0.39" rpy="0 0 1.5708 " />
      <geometry>
        <mesh filename="package://fourbythree_description/meshes/prototype4_link4.stl"/>
      </geometry>
      <material name="LightGrey">
      </material>
    </visual>
  </link>
  <link name="link4"/>
  
  
  
  <joint name="joint_5" type="revolute">
    <parent link="link4"/>
    <child link="link5_rotZ"/>
    <origin rpy="0.0 0 0.0" xyz="0 0 0.0"/>
    <axis xyz="0 0 1"/>
    <limit effort="40" lower="-1.57" upper="1.57" velocity="0.5"/>
  </joint>
  <joint name="joint_5_fixed" type="fixed">
    <parent link="link5_rotZ"/>
    <child link="link5"/>
    <origin rpy="-1.57079632679 0.0 0" xyz="0.0 0 0"/>
  </joint>
  <link name="link5_rotZ">
    <visual>
      <origin xyz=" 0 0 -0.01" rpy="0 1.5708 1.5708 " />
      <geometry>
        <mesh filename="package://fourbythree_description/meshes/prototype4_link5.stl"/>
      </geometry>
      <material name="LightGrey">
      </material>
    </visual>
  </link>
  <link name="link5"/>
  
  
  
  <joint name="joint_6" type="revolute">
    <parent link="link5"/>
    <child link="flange_rotZ"/>
    <origin rpy="0.0 0 0.0" xyz="0 0 0.26055"/>
    <axis xyz="0 0 1"/>
    <limit effort="40" lower="-2.8" upper="2.8" velocity="0.5"/>
  </joint>
  <joint name="joint_6_fixed" type="fixed">
    <parent link="flange_rotZ"/>
    <child link="flange"/>
    <origin rpy="0.0 0.0 0" xyz="0.0 0 0"/>
  </joint>
  
  
  <link name="flange_rotZ">
    <visual>
      <origin xyz=" 0 0 0" rpy="0 0  0 " />
      <geometry>
        <mesh filename="package://fourbythree_description/meshes/prototype4_flange.stl"/>
      </geometry>
      <material name="LightGrey">
      </material>
    </visual>
  </link>
  <link name="flange"/>
  
  
  <joint name="tool_adapter_joint" type="fixed">
    <origin rpy="0.0 0.0 0.0" xyz="0.0 0.0 0.01075"/>
    <parent link="flange"/>
    <child link="tool_adapter_link"/>
  </joint>
  <link name="tool_adapter_link">
    <inertial>
      <origin rpy="0.0 0.0 0.0" xyz="0.0 0.0 0.0"/>
      <mass value="1"/>
      <inertia ixx="1" ixy="0.0" ixz="0.0" iyy="1" iyz="0.0" izz="1"/>
    </inertial>
    <visual>
      <origin rpy="0 0.0 0" xyz="0.0 0.0 0.0"/>
      <geometry>
        <mesh filename="package://fourbythree_description/meshes/end_effector/tool_adapter.stl"/>
      </geometry>
      <material name="Black"/>
    </visual>
    <collision>
      <origin rpy="0 0.0 0" xyz="0.0 0.0 0.0"/>
      <geometry>
        <mesh filename="package://fourbythree_description/meshes/end_effector/tool_adapter.stl"/>
      </geometry>
      <material name="Black"/>
    </collision>
  </link>
  <!-- cameras -->
  <joint name="cameras_tcp/left_fixed_base_joint" type="fixed">
    <origin rpy="0.0 0.0 0.0" xyz="0.018 -0.101 0.05"/>
    <child link="cameras_tcp/left_link"/>
    <parent link="tool_adapter_link"/>
  </joint>
  <link name="cameras_tcp/left_link">
    <visual>
      <geometry>
        <mesh filename="package://fourbythree_description/meshes/mako_3d/visual/mako_3d_link/back.stl"/>
      </geometry>
      <material name="Grey"/>
    </visual>
    <visual>
      <geometry>
        <mesh filename="package://fourbythree_description/meshes/mako_3d/visual/mako_3d_link/bottom.stl"/>
      </geometry>
      <material name="Light Grey"/>
    </visual>
    <visual>
      <geometry>
        <mesh filename="package://fourbythree_description/meshes/mako_3d/visual/mako_3d_link/cover.stl"/>
      </geometry>
      <material name="Red"/>
    </visual>
    <visual>
      <geometry>
        <mesh filename="package://fourbythree_description/meshes/mako_3d/visual/mako_3d_link/ethernet.stl"/>
      </geometry>
      <material name="Light Grey"/>
    </visual>
    <visual>
      <geometry>
        <mesh filename="package://fourbythree_description/meshes/mako_3d/visual/mako_3d_link/front.stl"/>
      </geometry>
      <material name="Light Grey"/>
    </visual>
    <visual>
      <geometry>
        <mesh filename="package://fourbythree_description/meshes/mako_3d/visual/mako_3d_link/lens.stl"/>
      </geometry>
      <material name="Light Grey"/>
    </visual>
    <visual>
      <geometry>
        <mesh filename="package://fourbythree_description/meshes/mako_3d/visual/mako_3d_link/power.stl"/>
      </geometry>
      <material name="Light Grey"/>
    </visual>
    <collision>
      <geometry>
        <mesh filename="package://fourbythree_description/meshes/mako_3d/collision/mako_3d_link/case.stl"/>
      </geometry>
      <material name="Light Grey"/>
    </collision>
    <collision>
      <geometry>
        <mesh filename="package://fourbythree_description/meshes/mako_3d/collision/mako_3d_link/lens.stl"/>
      </geometry>
      <material name="Light Grey"/>
    </collision>
    <inertial>
      <!-- Estimated from reference sheet -->
      <mass value="0.08"/>
      <inertia ixx="1.0" ixy="0.0" ixz="0.0" iyy="1.0" iyz="0.0" izz="1.0"/>
    </inertial>
  </link>
  <!--Extensions -->
  <joint name="cameras_tcp/left_gazebo_optical_joint" type="fixed">
    <child link="cameras_tcp/left_gazebo_optical_link"/>
    <parent link="cameras_tcp/left_link"/>
    <origin rpy="0 -1.57079632679 -1.57079632679" xyz="0 0 0"/>
  </joint>
  <link name="cameras_tcp/left_gazebo_optical_link"/>

  <joint name="cameras_tcp/right_fixed_base_joint" type="fixed">
    <origin rpy="0.0 0.0 0.0" xyz="-0.036 0 0"/>
    <child link="cameras_tcp/right_link"/>
    <parent link="cameras_tcp/left_link"/>
  </joint>
  <link name="cameras_tcp/right_link">
    <visual>
      <geometry>
        <mesh filename="package://fourbythree_description/meshes/mako_3d/visual/mako_3d_link/back.stl"/>
      </geometry>
      <material name="Grey"/>
    </visual>
    <visual>
      <geometry>
        <mesh filename="package://fourbythree_description/meshes/mako_3d/visual/mako_3d_link/bottom.stl"/>
      </geometry>
      <material name="Light Grey"/>
    </visual>
    <visual>
      <geometry>
        <mesh filename="package://fourbythree_description/meshes/mako_3d/visual/mako_3d_link/cover.stl"/>
      </geometry>
      <material name="Red"/>
    </visual>
    <visual>
      <geometry>
        <mesh filename="package://fourbythree_description/meshes/mako_3d/visual/mako_3d_link/ethernet.stl"/>
      </geometry>
      <material name="Light Grey"/>
    </visual>
    <visual>
      <geometry>
        <mesh filename="package://fourbythree_description/meshes/mako_3d/visual/mako_3d_link/front.stl"/>
      </geometry>
      <material name="Light Grey"/>
    </visual>
    <visual>
      <geometry>
        <mesh filename="package://fourbythree_description/meshes/mako_3d/visual/mako_3d_link/lens.stl"/>
      </geometry>
      <material name="Light Grey"/>
    </visual>
    <visual>
      <geometry>
        <mesh filename="package://fourbythree_description/meshes/mako_3d/visual/mako_3d_link/power.stl"/>
      </geometry>
      <material name="Light Grey"/>
    </visual>
    <collision>
      <geometry>
        <mesh filename="package://fourbythree_description/meshes/mako_3d/collision/mako_3d_link/case.stl"/>
      </geometry>
      <material name="Light Grey"/>
    </collision>
    <collision>
      <geometry>
        <mesh filename="package://fourbythree_description/meshes/mako_3d/collision/mako_3d_link/lens.stl"/>
      </geometry>
      <material name="Light Grey"/>
    </collision>
    <inertial>
      <!-- Estimated from reference sheet -->
      <mass value="0.08"/>
      <inertia ixx="1.0" ixy="0.0" ixz="0.0" iyy="1.0" iyz="0.0" izz="1.0"/>
    </inertial>
  </link>
  <!--Extensions -->
  <joint name="cameras_tcp/right_gazebo_optical_joint" type="fixed">
    <child link="cameras_tcp/right_gazebo_optical_link"/>
    <parent link="cameras_tcp/right_link"/>
    <origin rpy="0 -1.57079632679 -1.57079632679" xyz="0 0 0"/>
  </joint>
  <link name="cameras_tcp/right_gazebo_optical_link"/>


  <joint name="schunk_adapter_fixed_base_joint" type="fixed">
    <origin rpy="0.0 0.0 .0" xyz="0 0 0.01075"/>
    <child link="schunk_adapter_link"/>
    <parent link="tool_adapter_link"/>
  </joint>
  <link name="schunk_adapter_link">
    <visual>
      <geometry>
        <mesh filename="package://fourbythree_description/meshes/schunk_adapter/visual/link_adapter/adapter_schunk_side.stl"/>
      </geometry>
      <material name="Grey"/>
    </visual>
    <visual>
      <geometry>
        <mesh filename="package://fourbythree_description/meshes/schunk_adapter/visual/link_adapter/adapter_robot_side.stl"/>
      </geometry>
      <material name="Grey"/>
    </visual>
    <visual>
      <geometry>
        <mesh filename="package://fourbythree_description/meshes/schunk_adapter/visual/link_adapter/union_nut.stl"/>
      </geometry>
      <material name="Black"/>
    </visual>
    <collision>
      <geometry>
        <mesh filename="package://fourbythree_description/meshes/schunk_adapter/collision/link_adapter/adapter.stl"/>
      </geometry>
      <material name="Grey"/>
    </collision>
    <inertial>
      <!-- Measured mass value -->
      <mass value="0.115"/>
      <inertia ixx="1.0" ixy="0.0" ixz="0.0" iyy="1.0" iyz="0.0" izz="1.0"/>
    </inertial>
  </link>

  <joint name="schunk_adapter_2_fixed_base_joint" type="fixed">
    <origin rpy="0.0 0.0 0.0" xyz="0 0 0.01"/>
    <child link="schunk_adapter_2_link"/>
    <parent link="schunk_adapter_link"/>
  </joint>
  <link name="schunk_adapter_2_link">
    <visual>
      <geometry>
        <mesh filename="package://fourbythree_description/meshes/schunk_adapter/visual/link_adapter/adapter_schunk_side.stl"/>
      </geometry>
      <material name="Grey"/>
    </visual>
    <visual>
      <geometry>
        <mesh filename="package://fourbythree_description/meshes/schunk_adapter/visual/link_adapter/adapter_robot_side.stl"/>
      </geometry>
      <material name="Grey"/>
    </visual>
    <visual>
      <geometry>
        <mesh filename="package://fourbythree_description/meshes/schunk_adapter/visual/link_adapter/union_nut.stl"/>
      </geometry>
      <material name="Black"/>
    </visual>
    <collision>
      <geometry>
        <mesh filename="package://fourbythree_description/meshes/schunk_adapter/collision/link_adapter/adapter.stl"/>
      </geometry>
      <material name="Grey"/>
    </collision>
    <inertial>
      <!-- Measured mass value -->
      <mass value="0.115"/>
      <inertia ixx="1.0" ixy="0.0" ixz="0.0" iyy="1.0" iyz="0.0" izz="1.0"/>
    </inertial>
  </link>
 
  <joint name="pluto10_support_joint" type="fixed">
    <origin rpy="0.0 0.0 .0" xyz="0 0 0.015"/>
    <parent link="schunk_adapter_2_link"/>
    <child link="pluto10_support_link"/>
  </joint>
  <link name="pluto10_support_link">
    <inertial>
      <origin rpy="0.0 0.0 0.0" xyz="0.0 0.0 0.0"/>
      <mass value="1"/>
      <inertia ixx="1" ixy="0.0" ixz="0.0" iyy="1" iyz="0.0" izz="1"/>
    </inertial>
    <visual>
      <origin rpy="0 0.0 0" xyz="0.0 0.0 0.0"/>
      <geometry>
        <mesh filename="package://fourbythree_description/meshes/end_effector/pluto10_support.stl"/>
      </geometry>
      <material name="Black"/>
    </visual>
    <collision>
      <origin rpy="0 0.0 0" xyz="0.0 0.0 0.0"/>
      <geometry>
        <mesh filename="package://fourbythree_description/meshes/end_effector/pluto10_support.stl"/>
      </geometry>
      <material name="Black"/>
    </collision>
  </link>
  <joint name="support_pluto10_joint" type="fixed">
    <origin rpy="0.0 0.0 1.57" xyz="0.0 0.06 0.025"/>
    <parent link="schunk_adapter_2_link"/>
    <child link="pluto10_link"/>
  </joint>
  <link name="pluto10_link">
    <inertial>
      <origin rpy="0.0 0.0 0.0" xyz="0.0 0.0 0.0"/>
      <mass value="1"/>
      <inertia ixx="1" ixy="0.0" ixz="0.0" iyy="1" iyz="0.0" izz="1"/>
    </inertial>
    <visual>
      <origin rpy="0 0.0 0" xyz="0.0 0.0 0.0"/>
      <geometry>
        <mesh filename="package://fourbythree_description/meshes/end_effector/pluto10.stl"/>
      </geometry>
      <material name="Black"/>
    </visual>
    <collision>
      <origin rpy="0 0.0 0" xyz="0.0 0.0 0.0"/>
      <geometry>
        <mesh filename="package://fourbythree_description/meshes/end_effector/pluto10.stl"/>
      </geometry>
      <material name="Black"/>
    </collision>
  </link>
  
  
  
</robot>

