<?xml version="1.0" ?>
<!-- =================================================================================== -->
<!-- |    This document was autogenerated by xacro from fourbythree_urdf_template.urdf.xacro | -->
<!-- |    EDITING THIS FILE BY HAND IS NOT RECOMMENDED                                 | -->
<!-- =================================================================================== -->
<robot name="prototype4" xmlns:xacro="http://ros.org/wiki/xacro">
  
  
  <material name="Blue">
    <color rgba="0 0.0 1.0 1.0"/>
  </material>
  <material name="Grey">
    <color rgba="0.5 0.5 0.5 1.0"/>
  </material>
  <material name="LightGrey">
    <color rgba="0.7 0.7 0.7 1.0"/>
  </material>
  <material name="DarkGrey">
    <color rgba="0.3 0.3 0.3 1.0"/>
  </material>
  
  
  <!-- RADIANT -->
  <!-- Nm -->
  <!-- PI/2 = 1.5708-->
  <!-- PI   = 3.1416-->
  
  
  <link name="base">
    <visual>
      <origin xyz="0 0 0" rpy="0 0 -3.1416" />
      <geometry>
       <mesh filename="package://fourbythree_description/meshes/prototype4_base.stl"/>
      </geometry>
      <material name="LightGrey">
      </material>
    </visual>
  </link>
  
  
  
  <joint name="joint_1" type="revolute">
    <parent link="base"/>
    <child link="link1_rotZ"/>
    <origin rpy="0.0 0 0.0" xyz="0 0 0.425"/>
    <axis xyz="0 0 1"/>
    <limit effort="250" lower="-2.8" upper="2.8" velocity="0.5"/>
  </joint>
  <joint name="joint_1_fixed" type="fixed">
    <parent link="link1_rotZ"/>
    <child link="link1"/>
    <origin rpy="1.57079632679 0.0 0" xyz="0.0 0 0"/>
  </joint>
  <link name="link1_rotZ">
    <visual>
      <origin xyz="0 -0.03 -0.02" rpy="0 0 -1.5708 " />
      <geometry>
        <mesh filename="package://fourbythree_description/meshes/prototype4_link1.stl"/>
      </geometry>
      <material name="LightGrey">
      </material>
    </visual>
  </link>
  <link name="link1"/>
  
  
  
  <joint name="joint_2" type="revolute">
    <parent link="link1"/>
    <child link="link2_rotZ"/>
    <origin rpy="0.0 0 1.57079632679" xyz="0 0 0.0"/>
    <axis xyz="0 0 1"/>
    <limit effort="250" lower="-1.8" upper="1.8" velocity="0.5"/>
  </joint>
  <joint name="joint_2_fixed" type="fixed">
    <parent link="link2_rotZ"/>
    <child link="link2"/>
    <origin rpy="0.0 0.0 0" xyz="0.6569 0 0"/>
  </joint>
  <link name="link2_rotZ">
    <visual>
      <origin xyz="0 0 0.09 " rpy=" 0 -1.572 3.1416" />
      <geometry>
        <mesh filename="package://fourbythree_description/meshes/prototype4_link2.stl"/>
      </geometry>
      <material name="LightGrey">
      </material>
    </visual>
  </link>
  <link name="link2"/>
  

  
  <joint name="joint_3" type="revolute">
    <parent link="link2"/>
    <child link="link3_rotZ"/>
    <origin rpy="0.0 0 -1.57079632679" xyz="0 0 0.006"/>
    <axis xyz="0 0 1"/>
    <limit effort="90" lower="-2.5" upper="2.5" velocity="0.5"/>
  </joint>
  <joint name="joint_3_fixed" type="fixed">
    <parent link="link3_rotZ"/>
    <child link="link3"/>
    <origin rpy="-1.57079632679 0.0 0" xyz="0.0 0 0"/>
  </joint>
  <link name="link3_rotZ">
    <visual>
      <origin xyz=" 0 0 0 " rpy=" 0 -1.5708 -1.5708" />
      <geometry>
        <mesh filename="package://fourbythree_description/meshes/prototype4_link3.stl"/>
      </geometry>
      <material name="LightGrey">
      </material>
    </visual>
  </link>
  <link name="link3"/>
  
  
  
  <joint name="joint_4" type="revolute">
    <parent link="link3"/>
    <child link="link4_rotZ"/>
    <origin rpy="0.0 0 0.0" xyz="0 0 0.56345"/>
    <axis xyz="0 0 1"/>
    <limit effort="40" lower="-2.8" upper="2.8" velocity="0.5"/>
  </joint>
  <joint name="joint_4_fixed" type="fixed">
    <parent link="link4_rotZ"/>
    <child link="link4"/>
    <origin rpy="1.57079632679 0.0 0" xyz="0.0 0 0"/>
  </joint>
  <link name="link4_rotZ">
    <visual>
      <origin xyz="0 0 -0.39" rpy="0 0 1.5708 " />
      <geometry>
        <mesh filename="package://fourbythree_description/meshes/prototype4_link4.stl"/>
      </geometry>
      <material name="LightGrey">
      </material>
    </visual>
  </link>
  <link name="link4"/>
  
  
  
  <joint name="joint_5" type="revolute">
    <parent link="link4"/>
    <child link="link5_rotZ"/>
    <origin rpy="0.0 0 0.0" xyz="0 0 0.0"/>
    <axis xyz="0 0 1"/>
    <limit effort="40" lower="-1.575" upper="1.575" velocity="0.5"/>
  </joint>
  <joint name="joint_5_fixed" type="fixed">
    <parent link="link5_rotZ"/>
    <child link="link5"/>
    <origin rpy="-1.57079632679 0.0 0" xyz="0.0 0 0"/>
  </joint>
  <link name="link5_rotZ">
    <visual>
      <origin xyz=" 0 0 -0.01" rpy="0 1.5708 1.5708 " />
      <geometry>
        <mesh filename="package://fourbythree_description/meshes/prototype4_link5.stl"/>
      </geometry>
      <material name="LightGrey">
      </material>
    </visual>
  </link>
  <link name="link5"/>
  
  
  
  <joint name="joint_6" type="revolute">
    <parent link="link5"/>
    <child link="flange_rotZ"/>
    <origin rpy="0.0 0 0.0" xyz="0 0 0.26055"/>
    <axis xyz="0 0 1"/>
    <limit effort="40" lower="-2.8" upper="2.8" velocity="0.5"/>
  </joint>
  <joint name="joint_6_fixed" type="fixed">
    <parent link="flange_rotZ"/>
    <child link="flange"/>
    <origin rpy="0.0 0.0 0" xyz="0.0 0 0"/>
  </joint>
  
  
  <link name="flange_rotZ">
    <visual>
      <origin xyz=" 0 0 0" rpy="0 0  0 " />
      <geometry>
        <mesh filename="package://fourbythree_description/meshes/prototype4_flange.stl"/>
      </geometry>
      <material name="LightGrey">
      </material>
    </visual>
  </link>
  <link name="flange"/>
  
  
</robot>

