<robot name="prototype2">
  
    <link name="base">
        <inertial>
            <origin xyz="0 0 0.0990895321440592" rpy="0 0 0" />
            <mass value="253.525333333333" />
            <inertia ixx="4.18309607973971" ixy="-2.39753911095338E-16" ixz="2.91074903770969E-17" iyy="4.18309607973971" iyz="4.7236418800763E-17" izz="6.70311765333334" />
        </inertial>
        <visual>
            <origin xyz="0 0 0" rpy="0 0 0" />
            <geometry>
                <mesh filename="package://fourbythree_description/meshes/prototype2_base.stl" />
            </geometry>
            <material name="">
                <color rgba="0.647058823529412 0.619607843137255 0.588235294117647 1" />
            </material>
        </visual>    
    </link>
    
    <link name="link_1">
        <inertial>
            <origin xyz="-0.0443267514949205 4.17458899834022E-05 0.371569513138346" rpy="0 0 0" />
            <mass value="72.7486650193488" />
            <inertia ixx="2.66763226671502" 
                     ixy="-4.54746430176038E-05" 
                     ixz="-0.39683506701499" 
                     iyy="2.91996037500999" 
                     iyz="0.000273701664248249" 
                     izz="0.489815571859748" />
        </inertial>
        <visual>
            <origin xyz="0 0 0" rpy="0 0 -1.570796327" />
            <geometry>
                <mesh filename="package://fourbythree_description/meshes/prototype2_link_1.stl" />
            </geometry>
            <material name="">
                <color rgba="0.647058823529412 0.619607843137255 0.588235294117647 1" />
            </material>
        </visual>
    </link>
    
    <link name="link_2">
        <inertial>
            <origin xyz="-0.141356232424118 0 0.0652085598166571" rpy="1.5708 0 0" />
            <mass value="47.3273241083633" />
            <inertia ixx="0.129118244613837" 
                     ixy="1.40177310772871E-07" 
                     ixz="-0.0256044142579582" 
                     iyy="1.26536972903653" 
                     iyz="1.01962720485977E-07" 
                     izz="1.26817604835663" />
        </inertial>
        <visual>
            <origin xyz="0 0 0.05" rpy="0 0 0" />
            <geometry>
                <mesh filename="package://fourbythree_description/meshes/prototype2_link_2.stl" />
            </geometry>
            <material name="">
                <color rgba="0.647058823529412 0.619607843137255 0.588235294117647 1" />
            </material>
        </visual>
    </link>

    <link name="link_3">
        <inertial>
            <origin xyz="0.143098508131295 0 0.0839477120173431" rpy="0 0 0" />
            <mass value="39.1162237962465" />
            <inertia ixx="0.0972713237779315" 
                     ixy="2.87522511938195E-07" 
                     ixz="0.0450720613591072" 
                     iyy="0.710167085573886" 
                     iyz="1.64081926222993E-07" 
                     izz="0.684964326880907" />
        </inertial>
        <visual>
            <origin xyz="0 0 0.05" rpy="3.1416 0 0" />
            <geometry>
                <mesh filename="package://fourbythree_description/meshes/prototype2_link_3.stl" />
            </geometry>
            <material name="">
                <color rgba="0.647058823529412 0.619607843137255 0.588235294117647 1" />
            </material>
        </visual>
    </link>
    
    <link name="link_4">
        <inertial>
            <origin xyz="-0.0375920451703105 0 0.0768555645788675" rpy="0 0 0" />
            <mass value="22.1846303925778" />
            <inertia ixx="0.0523613500364305" 
                     ixy="-1.23143558223779E-08" 
                     ixz="-0.00596010682459545" 
                     iyy="0.109918992669326" 
                     iyz="6.96589372018293E-09" 
                     izz="0.0984266547117798" />
        </inertial>
        <visual>
            <origin xyz="0 0 0.025" rpy="0 0 0" />
            <geometry>
                <mesh filename="package://fourbythree_description/meshes/prototype2_link_4.stl" />
            </geometry>
            <material name="">
                <color rgba="0.647058823529412 0.619607843137255 0.588235294117647 1" />
            </material>
        </visual>
    </link>
    
     <link name="link_5">
        <inertial>
            <origin xyz="0 0 0.0571563163041219" rpy="0 0 0" />
            <mass value="8.81605733093453" />
            <inertia ixx="0.0163023394294274" 
                     ixy="-1.68051336735253E-18" 
                     ixz="3.25260651745651E-18" 
                     iyy="0.0163023394294274" 
                     iyz="8.67361737988404E-19" 
                     izz="0.0131360832115547" />
        </inertial>
        <visual>
            <origin xyz="0 0 0" rpy="0 0 0" />
            <geometry>
                <mesh filename="package://fourbythree_description/meshes/prototype2_link_5.stl" />
            </geometry>
            <material name="">
                <color rgba="0.647058823529412 0.619607843137255 0.588235294117647 1" />
            </material>
        </visual>
    </link>
    
    
    
    
    <joint name="joint_1" type="revolute">
        <origin xyz="0 0 0.2" rpy="0 0 0" />
        <parent link="base" />
        <child link="link_1" />
        <axis xyz="0 0 1" />
        <limit lower="-2.967" upper="2.967" effort="70" velocity="0.2" />
    </joint>
    
    <joint name="joint_2" type="revolute">
        <origin xyz="0 0 0.49506" rpy="0 1.5708 -1.5708" />
        <parent link="link_1" />
        <child link="link_2" />
        <axis xyz="0 0 1" />
        <limit lower="-3.2351" upper="2.699" effort="70" velocity="0.2" />
    </joint>
    
    <joint name="joint_3" type="revolute">
        <origin xyz="-0.3436 0 0" rpy="0 0 -3.1416" />
        <parent link="link_2" />
        <child link="link_3" />
        <axis xyz="0 0 1" />
        <limit lower="-1.6645" upper="4.2696" effort="35" velocity="0.2" />
    </joint>
    
    <joint name="joint_4" type="revolute">
        <origin xyz="0.2862 0 0" rpy="0 0 -3.1416" />
        <parent link="link_3" />
        <child link="link_4" />
        <axis xyz="0 0 1" />
        <limit lower="-3.2727" upper="2.6615" effort="35" velocity="0.2" />
    </joint>
    
    <joint name="joint_5" type="revolute">
        <origin xyz="-0.1571 0 0.11" rpy="0 -1.5708 0" />
        <parent link="link_4" />
        <child link="link_5" />
        <axis xyz="0 0 1" />
        <limit lower="-2.9671" upper="2.9671" effort="35" velocity="0.2" />
    </joint>
    
</robot>
